Workbook

Sheet Code Output
A1: ID | B1: Measure Name | C1: Sector | D1: Program | E1: Market | F1: Gas Utility | G1: Electric Utility | H1: Baseline Condition | I1: Efficient Condition | J1: Complementary Condition | K1: Building Type | L1: Measure Life (yrs) | M1: Incremental Cost ($) | N1: Annual O&M Savings ($) | O1: Cost of Baseline Replacement ($) | P1: Deferred Replacement Credit ($) | Q1: Deferred Replacement Year X ($) | R1: Present Value Used ($) | S1: kW-kWh Ratio | T1: Water Savings (gallons) | U1: Energy Savings 1 End Use | V1: Energy Savings 1 Value | W1: Energy Savings 1 Fuel Type | X1: Energy Savings 1 Units | Y1: Energy Savings 2 End Use | Z1: Energy Savings 2 Value | AA1: Energy Savings 2 Fuel Type | AB1: Energy Savings 2 Units | AC1: Energy Savings 3 End Use | AD1: Energy Savings 3 Value | AE1: Energy Savings 3 Fuel Type | AF1: Energy Savings 3 Units
A2: 1 | B2: furnace_natural_gas_baseline_residential_to_furnace_natural_gas_efficient_residential | C2: residential | D2: LIRNC | E2: NC | F2: Methaners | G2: ElecCo | H2: furnace_natural_gas_baseline_residential | I2: furnace_natural_gas_efficient_residential | K2: single_family_li | L2: 10 | M2: 700 | N2: 0 | O2: 0 | P2: 0 | Q2: 0 | R2: 0 | S2: 40 | T2: 0 | U2: space_heating | V2: 80 | W2: natural_gas | X2: therms | Y2: space_heating | Z2: 30 | AA2: electricity | AB2: kWh
A3: 2 | B3: furnace_natural_gas_baseline_residential_to_furnace_natural_gas_efficient_residential | C3: residential | D3: NLIRNC | E3: NC | F3: Methaners | G3: ElecCo | H3: furnace_natural_gas_baseline_residential | I3: furnace_natural_gas_efficient_residential | K3: multi_family | L3: 10 | M3: 700 | N3: 0 | O3: 0 | P3: 0 | Q3: 0 | R3: 0 | S3: 90 | T3: 0 | U3: space_heating | V3: 180 | W3: natural_gas | X3: therms | Y3: space_heating | Z3: 67.5 | AA3: electricity | AB3: kWh
A4: 3 | B4: furnace_natural_gas_baseline_residential_to_furnace_natural_gas_efficient_residential | C4: residential | D4: NLIRNC | E4: NC | F4: Methaners | G4: ElecCo | H4: furnace_natural_gas_baseline_residential | I4: furnace_natural_gas_efficient_residential | K4: single_family | L4: 10 | M4: 700 | N4: 0 | O4: 0 | P4: 0 | Q4: 0 | R4: 0 | S4: 40 | T4: 0 | U4: space_heating | V4: 80 | W4: natural_gas | X4: therms | Y4: space_heating | Z4: 30 | AA4: electricity | AB4: kWh
A5: 4 | B5: furnace_natural_gas_baseline_residential_to_furnace_natural_gas_efficient_residential | C5: residential | D5: LIRNC | E5: NC | F5: Methaners | G5: ElecCo | H5: furnace_natural_gas_baseline_residential | I5: furnace_natural_gas_efficient_residential | K5: multi_family_li | L5: 10 | M5: 700 | N5: 0 | O5: 0 | P5: 0 | Q5: 0 | R5: 0 | S5: 90 | T5: 0 | U5: space_heating | V5: 180 | W5: natural_gas | X5: therms | Y5: space_heating | Z5: 67.5 | AA5: electricity | AB5: kWh
A6: 5 | B6: furnace_natural_gas_baseline_residential_to_furnace_natural_gas_efficient_residential | C6: residential | D6: LIRNC | E6: NC | F6: SuperGas | G6: ElecCo | H6: furnace_natural_gas_baseline_residential | I6: furnace_natural_gas_efficient_residential | K6: single_family_li | L6: 10 | M6: 700 | N6: 0 | O6: 0 | P6: 0 | Q6: 0 | R6: 0 | S6: 40 | T6: 0 | U6: space_heating | V6: 80 | W6: natural_gas | X6: therms | Y6: space_heating | Z6: 30 | AA6: electricity | AB6: kWh
A7: 6 | B7: furnace_natural_gas_baseline_residential_to_furnace_natural_gas_efficient_residential | C7: residential | D7: NLIRNC | E7: NC | F7: SuperGas | G7: ElecCo | H7: furnace_natural_gas_baseline_residential | I7: furnace_natural_gas_efficient_residential | K7: multi_family | L7: 10 | M7: 700 | N7: 0 | O7: 0 | P7: 0 | Q7: 0 | R7: 0 | S7: 90 | T7: 0 | U7: space_heating | V7: 180 | W7: natural_gas | X7: therms | Y7: space_heating | Z7: 67.5 | AA7: electricity | AB7: kWh
A8: 7 | B8: furnace_natural_gas_baseline_residential_to_furnace_natural_gas_efficient_residential | C8: residential | D8: NLIRNC | E8: NC | F8: SuperGas | G8: ElecCo | H8: furnace_natural_gas_baseline_residential | I8: furnace_natural_gas_efficient_residential | K8: single_family | L8: 10 | M8: 700 | N8: 0 | O8: 0 | P8: 0 | Q8: 0 | R8: 0 | S8: 40 | T8: 0 | U8: space_heating | V8: 80 | W8: natural_gas | X8: therms | Y8: space_heating | Z8: 30 | AA8: electricity | AB8: kWh
A9: 8 | B9: furnace_natural_gas_baseline_residential_to_furnace_natural_gas_efficient_residential | C9: residential | D9: LIRNC | E9: NC | F9: SuperGas | G9: ElecCo | H9: furnace_natural_gas_baseline_residential | I9: furnace_natural_gas_efficient_residential | K9: multi_family_li | L9: 10 | M9: 700 | N9: 0 | O9: 0 | P9: 0 | Q9: 0 | R9: 0 | S9: 90 | T9: 0 | U9: space_heating | V9: 180 | W9: natural_gas | X9: therms | Y9: space_heating | Z9: 67.5 | AA9: electricity | AB9: kWh
A10: 9 | B10: furnace_natural_gas_baseline_residential_to_furnace_natural_gas_efficient_residential | C10: residential | D10: LIRNC | E10: NC | F10: SuperGas | G10: FreshTricity | H10: furnace_natural_gas_baseline_residential | I10: furnace_natural_gas_efficient_residential | K10: single_family_li | L10: 10 | M10: 700 | N10: 0 | O10: 0 | P10: 0 | Q10: 0 | R10: 0 | S10: 40 | T10: 0 | U10: space_heating | V10: 80 | W10: natural_gas | X10: therms | Y10: space_heating | Z10: 30 | AA10: electricity | AB10: kWh
A11: 10 | B11: furnace_natural_gas_baseline_residential_to_furnace_natural_gas_efficient_residential | C11: residential | D11: NLIRNC | E11: NC | F11: SuperGas | G11: FreshTricity | H11: furnace_natural_gas_baseline_residential | I11: furnace_natural_gas_efficient_residential | K11: multi_family | L11: 10 | M11: 700 | N11: 0 | O11: 0 | P11: 0 | Q11: 0 | R11: 0 | S11: 90 | T11: 0 | U11: space_heating | V11: 180 | W11: natural_gas | X11: therms | Y11: space_heating | Z11: 67.5 | AA11: electricity | AB11: kWh
A12: 11 | B12: furnace_natural_gas_baseline_residential_to_furnace_natural_gas_efficient_residential | C12: residential | D12: NLIRNC | E12: NC | F12: SuperGas | G12: FreshTricity | H12: furnace_natural_gas_baseline_residential | I12: furnace_natural_gas_efficient_residential | K12: single_family | L12: 10 | M12: 700 | N12: 0 | O12: 0 | P12: 0 | Q12: 0 | R12: 0 | S12: 40 | T12: 0 | U12: space_heating | V12: 80 | W12: natural_gas | X12: therms | Y12: space_heating | Z12: 30 | AA12: electricity | AB12: kWh
A13: 12 | B13: furnace_natural_gas_baseline_residential_to_furnace_natural_gas_efficient_residential | C13: residential | D13: LIRNC | E13: NC | F13: SuperGas | G13: FreshTricity | H13: furnace_natural_gas_baseline_residential | I13: furnace_natural_gas_efficient_residential | K13: multi_family_li | L13: 10 | M13: 700 | N13: 0 | O13: 0 | P13: 0 | Q13: 0 | R13: 0 | S13: 90 | T13: 0 | U13: space_heating | V13: 180 | W13: natural_gas | X13: therms | Y13: space_heating | Z13: 67.5 | AA13: electricity | AB13: kWh
... A85: 84 | B85: furnace_natural_gas_baseline_residential_to_furnace_natural_gas_efficient_residential | C85: residential | D85: LIRRENO | E85: RENO | F85: SuperGas | G85: GreenElec | H85: furnace_natural_gas_baseline_residential | I85: furnace_natural_gas_efficient_residential | K85: multi_family_li | L85: 10 | M85: 700 | N85: 0 | O85: 0 | P85: 0 | Q85: 0 | R85: 0 | S85: 90 | T85: 0 | U85: space_heating | V85: 180 | W85: natural_gas | X85: therms | Y85: space_heating | Z85: 67.5 | AA85: electricity | AB85: kWh
A86: 85 | B86: furnace_natural_gas_baseline_residential_to_cchp_electricity_efficient_residential | C86: residential | D86: LIRNC | E86: NC | F86: Methaners | G86: ElecCo | H86: furnace_natural_gas_baseline_residential | I86: cchp_electricity_efficient_residential | K86: single_family_li | L86: 10 | M86: 2300 | N86: 100 | O86: 0 | P86: 0 | Q86: 0 | R86: 0 | S86: 120 | T86: 0 | U86: space_heating | V86: 0 | W86: natural_gas | X86: therms | Y86: space_heating | Z86: -1600 | AA86: electricity | AB86: kWh | AC86: cooling | AD86: -700 | AE86: electricity | AF86: kWh
A87: 86 | B87: furnace_natural_gas_baseline_residential_to_cchp_electricity_efficient_residential | C87: residential | D87: NLIRNC | E87: NC | F87: Methaners | G87: ElecCo | H87: furnace_natural_gas_baseline_residential | I87: cchp_electricity_efficient_residential | K87: multi_family | L87: 10 | M87: 2300 | N87: 100 | O87: 0 | P87: 0 | Q87: 0 | R87: 0 | S87: 150 | T87: 0 | U87: space_heating | V87: 400 | W87: natural_gas | X87: therms | Y87: space_heating | Z87: -1850 | AA87: electricity | AB87: kWh | AC87: cooling | AD87: -875 | AE87: electricity | AF87: kWh
A88: 87 | B88: furnace_natural_gas_baseline_residential_to_cchp_electricity_efficient_residential | C88: residential | D88: NLIRNC | E88: NC | F88: Methaners | G88: ElecCo | H88: furnace_natural_gas_baseline_residential | I88: cchp_electricity_efficient_residential | K88: single_family | L88: 10 | M88: 2300 | N88: 100 | O88: 0 | P88: 0 | Q88: 0 | R88: 0 | S88: 120 | T88: 0 | U88: space_heating | V88: 0 | W88: natural_gas | X88: therms | Y88: space_heating | Z88: -1600 | AA88: electricity | AB88: kWh | AC88: cooling | AD88: -700 | AE88: electricity | AF88: kWh
A89: 88 | B89: furnace_natural_gas_baseline_residential_to_cchp_electricity_efficient_residential | C89: residential | D89: LIRNC | E89: NC | F89: Methaners | G89: ElecCo | H89: furnace_natural_gas_baseline_residential | I89: cchp_electricity_efficient_residential | K89: multi_family_li | L89: 10 | M89: 2300 | N89: 100 | O89: 0 | P89: 0 | Q89: 0 | R89: 0 | S89: 150 | T89: 0 | U89: space_heating | V89: 400 | W89: natural_gas | X89: therms | Y89: space_heating | Z89: -1850 | AA89: electricity | AB89: kWh | AC89: cooling | AD89: -875 | AE89: electricity | AF89: kWh
A90: 89 | B90: furnace_natural_gas_baseline_residential_to_cchp_electricity_efficient_residential | C90: residential | D90: LIRNC | E90: NC | F90: SuperGas | G90: ElecCo | H90: furnace_natural_gas_baseline_residential | I90: cchp_electricity_efficient_residential | K90: single_family_li | L90: 10 | M90: 2300 | N90: 100 | O90: 0 | P90: 0 | Q90: 0 | R90: 0 | S90: 120 | T90: 0 | U90: space_heating | V90: 0 | W90: natural_gas | X90: therms | Y90: space_heating | Z90: -1600 | AA90: electricity | AB90: kWh | AC90: cooling | AD90: -700 | AE90: electricity | AF90: kWh
A91: 90 | B91: furnace_natural_gas_baseline_residential_to_cchp_electricity_efficient_residential | C91: residential | D91: NLIRNC | E91: NC | F91: SuperGas | G91: ElecCo | H91: furnace_natural_gas_baseline_residential | I91: cchp_electricity_efficient_residential | K91: multi_family | L91: 10 | M91: 2300 | N91: 100 | O91: 0 | P91: 0 | Q91: 0 | R91: 0 | S91: 150 | T91: 0 | U91: space_heating | V91: 400 | W91: natural_gas | X91: therms | Y91: space_heating | Z91: -1850 | AA91: electricity | AB91: kWh | AC91: cooling | AD91: -875 | AE91: electricity | AF91: kWh
A92: 91 | B92: furnace_natural_gas_baseline_residential_to_cchp_electricity_efficient_residential | C92: residential | D92: NLIRNC | E92: NC | F92: SuperGas | G92: ElecCo | H92: furnace_natural_gas_baseline_residential | I92: cchp_electricity_efficient_residential | K92: single_family | L92: 10 | M92: 2300 | N92: 100 | O92: 0 | P92: 0 | Q92: 0 | R92: 0 | S92: 120 | T92: 0 | U92: space_heating | V92: 0 | W92: natural_gas | X92: therms | Y92: space_heating | Z92: -1600 | AA92: electricity | AB92: kWh | AC92: cooling | AD92: -700 | AE92: electricity | AF92: kWh
A93: 92 | B93: furnace_natural_gas_baseline_residential_to_cchp_electricity_efficient_residential | C93: residential | D93: LIRNC | E93: NC | F93: SuperGas | G93: ElecCo | H93: furnace_natural_gas_baseline_residential | I93: cchp_electricity_efficient_residential | K93: multi_family_li | L93: 10 | M93: 2300 | N93: 100 | O93: 0 | P93: 0 | Q93: 0 | R93: 0 | S93: 150 | T93: 0 | U93: space_heating | V93: 400 | W93: natural_gas | X93: therms | Y93: space_heating | Z93: -1850 | AA93: electricity | AB93: kWh | AC93: cooling | AD93: -875 | AE93: electricity | AF93: kWh
A94: 93 | B94: furnace_natural_gas_baseline_residential_to_cchp_electricity_efficient_residential | C94: residential | D94: LIRNC | E94: NC | F94: SuperGas | G94: FreshTricity | H94: furnace_natural_gas_baseline_residential | I94: cchp_electricity_efficient_residential | K94: single_family_li | L94: 10 | M94: 2300 | N94: 100 | O94: 0 | P94: 0 | Q94: 0 | R94: 0 | S94: 120 | T94: 0 | U94: space_heating | V94: 0 | W94: natural_gas | X94: therms | Y94: space_heating | Z94: -1600 | AA94: electricity | AB94: kWh | AC94: cooling | AD94: -700 | AE94: electricity | AF94: kWh
A95: 94 | B95: furnace_natural_gas_baseline_residential_to_cchp_electricity_efficient_residential | C95: residential | D95: NLIRNC | E95: NC | F95: SuperGas | G95: FreshTricity | H95: furnace_natural_gas_baseline_residential | I95: cchp_electricity_efficient_residential | K95: multi_family | L95: 10 | M95: 2300 | N95: 100 | O95: 0 | P95: 0 | Q95: 0 | R95: 0 | S95: 150 | T95: 0 | U95: space_heating | V95: 400 | W95: natural_gas | X95: therms | Y95: space_heating | Z95: -1850 | AA95: electricity | AB95: kWh | AC95: cooling | AD95: -875 | AE95: electricity | AF95: kWh
A96: 95 | B96: furnace_natural_gas_baseline_residential_to_cchp_electricity_efficient_residential | C96: residential | D96: NLIRNC | E96: NC | F96: SuperGas | G96: FreshTricity | H96: furnace_natural_gas_baseline_residential | I96: cchp_electricity_efficient_residential | K96: single_family | L96: 10 | M96: 2300 | N96: 100 | O96: 0 | P96: 0 | Q96: 0 | R96: 0 | S96: 120 | T96: 0 | U96: space_heating | V96: 0 | W96: natural_gas | X96: therms | Y96: space_heating | Z96: -1600 | AA96: electricity | AB96: kWh | AC96: cooling | AD96: -700 | AE96: electricity | AF96: kWh
A97: 96 | B97: furnace_natural_gas_baseline_residential_to_cchp_electricity_efficient_residential | C97: residential | D97: LIRNC | E97: NC | F97: SuperGas | G97: FreshTricity | H97: furnace_natural_gas_baseline_residential | I97: cchp_electricity_efficient_residential | K97: multi_family_li | L97: 10 | M97: 2300 | N97: 100 | O97: 0 | P97: 0 | Q97: 0 | R97: 0 | S97: 150 | T97: 0 | U97: space_heating | V97: 400 | W97: natural_gas | X97: therms | Y97: space_heating | Z97: -1850 | AA97: electricity | AB97: kWh | AC97: cooling | AD97: -875 | AE97: electricity | AF97: kWh
... A169: 168 | B169: furnace_natural_gas_baseline_residential_to_cchp_electricity_efficient_residential | C169: residential | D169: LIRRENO | E169: RENO | F169: SuperGas | G169: GreenElec | H169: furnace_natural_gas_baseline_residential | I169: cchp_electricity_efficient_residential | K169: multi_family_li | L169: 10 | M169: 2300 | N169: 100 | O169: 0 | P169: 0 | Q169: 0 | R169: 0 | S169: 150 | T169: 0 | U169: space_heating | V169: 400 | W169: natural_gas | X169: therms | Y169: space_heating | Z169: -1850 | AA169: electricity | AB169: kWh | AC169: cooling | AD169: -875 | AE169: electricity | AF169: kWh
A170: 169 | B170: room_ac_electricity_baseline_residential_to_air_conditioner_electricity_efficient_residential | C170: residential | D170: LIRNC | E170: NC | F170: Methaners | G170: ElecCo | H170: room_ac_electricity_baseline_residential | I170: air_conditioner_electricity_efficient_residential | J170: room_ac_electricity_baseline_residential | K170: single_family_li | L170: 10 | M170: 1850 | N170: 100 | O170: 0 | P170: 0 | Q170: 0 | R170: 0 | S170: 120 | T170: 0 | U170: cooling | V170: -400 | W170: electricity | X170: kWh
A171: 170 | B171: room_ac_electricity_baseline_residential_to_air_conditioner_electricity_efficient_residential | C171: residential | D171: NLIRNC | E171: NC | F171: Methaners | G171: ElecCo | H171: room_ac_electricity_baseline_residential | I171: air_conditioner_electricity_efficient_residential | J171: room_ac_electricity_baseline_residential | K171: multi_family | L171: 10 | M171: 1850 | N171: 100 | O171: 0 | P171: 0 | Q171: 0 | R171: 0 | S171: 150 | T171: 0 | U171: cooling | V171: -800 | W171: electricity | X171: kWh
A172: 171 | B172: room_ac_electricity_baseline_residential_to_air_conditioner_electricity_efficient_residential | C172: residential | D172: NLIRNC | E172: NC | F172: Methaners | G172: ElecCo | H172: room_ac_electricity_baseline_residential | I172: air_conditioner_electricity_efficient_residential | J172: room_ac_electricity_baseline_residential | K172: single_family | L172: 10 | M172: 1850 | N172: 100 | O172: 0 | P172: 0 | Q172: 0 | R172: 0 | S172: 120 | T172: 0 | U172: cooling | V172: -400 | W172: electricity | X172: kWh
A173: 172 | B173: room_ac_electricity_baseline_residential_to_air_conditioner_electricity_efficient_residential | C173: residential | D173: LIRNC | E173: NC | F173: Methaners | G173: ElecCo | H173: room_ac_electricity_baseline_residential | I173: air_conditioner_electricity_efficient_residential | J173: room_ac_electricity_baseline_residential | K173: multi_family_li | L173: 10 | M173: 1850 | N173: 100 | O173: 0 | P173: 0 | Q173: 0 | R173: 0 | S173: 150 | T173: 0 | U173: cooling | V173: -800 | W173: electricity | X173: kWh
A174: 173 | B174: room_ac_electricity_baseline_residential_to_air_conditioner_electricity_efficient_residential | C174: residential | D174: LIRNC | E174: NC | F174: SuperGas | G174: ElecCo | H174: room_ac_electricity_baseline_residential | I174: air_conditioner_electricity_efficient_residential | J174: room_ac_electricity_baseline_residential | K174: single_family_li | L174: 10 | M174: 1850 | N174: 100 | O174: 0 | P174: 0 | Q174: 0 | R174: 0 | S174: 120 | T174: 0 | U174: cooling | V174: -400 | W174: electricity | X174: kWh
A175: 174 | B175: room_ac_electricity_baseline_residential_to_air_conditioner_electricity_efficient_residential | C175: residential | D175: NLIRNC | E175: NC | F175: SuperGas | G175: ElecCo | H175: room_ac_electricity_baseline_residential | I175: air_conditioner_electricity_efficient_residential | J175: room_ac_electricity_baseline_residential | K175: multi_family | L175: 10 | M175: 1850 | N175: 100 | O175: 0 | P175: 0 | Q175: 0 | R175: 0 | S175: 150 | T175: 0 | U175: cooling | V175: -800 | W175: electricity | X175: kWh
A176: 175 | B176: room_ac_electricity_baseline_residential_to_air_conditioner_electricity_efficient_residential | C176: residential | D176: NLIRNC | E176: NC | F176: SuperGas | G176: ElecCo | H176: room_ac_electricity_baseline_residential | I176: air_conditioner_electricity_efficient_residential | J176: room_ac_electricity_baseline_residential | K176: single_family | L176: 10 | M176: 1850 | N176: 100 | O176: 0 | P176: 0 | Q176: 0 | R176: 0 | S176: 120 | T176: 0 | U176: cooling | V176: -400 | W176: electricity | X176: kWh
A177: 176 | B177: room_ac_electricity_baseline_residential_to_air_conditioner_electricity_efficient_residential | C177: residential | D177: LIRNC | E177: NC | F177: SuperGas | G177: ElecCo | H177: room_ac_electricity_baseline_residential | I177: air_conditioner_electricity_efficient_residential | J177: room_ac_electricity_baseline_residential | K177: multi_family_li | L177: 10 | M177: 1850 | N177: 100 | O177: 0 | P177: 0 | Q177: 0 | R177: 0 | S177: 150 | T177: 0 | U177: cooling | V177: -800 | W177: electricity | X177: kWh
A178: 177 | B178: room_ac_electricity_baseline_residential_to_air_conditioner_electricity_efficient_residential | C178: residential | D178: LIRNC | E178: NC | F178: SuperGas | G178: FreshTricity | H178: room_ac_electricity_baseline_residential | I178: air_conditioner_electricity_efficient_residential | J178: room_ac_electricity_baseline_residential | K178: single_family_li | L178: 10 | M178: 1850 | N178: 100 | O178: 0 | P178: 0 | Q178: 0 | R178: 0 | S178: 120 | T178: 0 | U178: cooling | V178: -400 | W178: electricity | X178: kWh
A179: 178 | B179: room_ac_electricity_baseline_residential_to_air_conditioner_electricity_efficient_residential | C179: residential | D179: NLIRNC | E179: NC | F179: SuperGas | G179: FreshTricity | H179: room_ac_electricity_baseline_residential | I179: air_conditioner_electricity_efficient_residential | J179: room_ac_electricity_baseline_residential | K179: multi_family | L179: 10 | M179: 1850 | N179: 100 | O179: 0 | P179: 0 | Q179: 0 | R179: 0 | S179: 150 | T179: 0 | U179: cooling | V179: -800 | W179: electricity | X179: kWh
A180: 179 | B180: room_ac_electricity_baseline_residential_to_air_conditioner_electricity_efficient_residential | C180: residential | D180: NLIRNC | E180: NC | F180: SuperGas | G180: FreshTricity | H180: room_ac_electricity_baseline_residential | I180: air_conditioner_electricity_efficient_residential | J180: room_ac_electricity_baseline_residential | K180: single_family | L180: 10 | M180: 1850 | N180: 100 | O180: 0 | P180: 0 | Q180: 0 | R180: 0 | S180: 120 | T180: 0 | U180: cooling | V180: -400 | W180: electricity | X180: kWh
A181: 180 | B181: room_ac_electricity_baseline_residential_to_air_conditioner_electricity_efficient_residential | C181: residential | D181: LIRNC | E181: NC | F181: SuperGas | G181: FreshTricity | H181: room_ac_electricity_baseline_residential | I181: air_conditioner_electricity_efficient_residential | J181: room_ac_electricity_baseline_residential | K181: multi_family_li | L181: 10 | M181: 1850 | N181: 100 | O181: 0 | P181: 0 | Q181: 0 | R181: 0 | S181: 150 | T181: 0 | U181: cooling | V181: -800 | W181: electricity | X181: kWh
... A337: 336 | B337: air_conditioner_electricity_baseline_residential_to_air_conditioner_electricity_efficient_residential | C337: residential | D337: LIRRENO | E337: RENO | F337: SuperGas | G337: GreenElec | H337: air_conditioner_electricity_baseline_residential | I337: air_conditioner_electricity_efficient_residential | J337: air_conditioner_electricity_baseline_residential | K337: multi_family_li | L337: 10 | M337: 550 | N337: 100 | O337: 0 | P337: 0 | Q337: 0 | R337: 0 | S337: 150 | T337: 0 | U337: cooling | V337: 1125 | W337: electricity | X337: kWh
...

Sheet Deferred Replacement QC
A1: ID | B1: Measure Name | C1: Sector | D1: Program | E1: Market | F1: Gas Utility | G1: Electric Utility | H1: Baseline Condition | I1: Efficient Condition | J1: Complementary Condition | K1: Building Type | L1: Measure Life (yrs) | M1: Incremental Cost ($) | N1: Annual O&M Savings ($) | O1: Cost of Baseline Replacement ($) | P1: Deferred Replacement Credit ($) | Q1: Deferred Replacement Year X ($) | R1: Present Value Used ($) | S1: kW-kWh Ratio | T1: Water Savings (gallons) | U1: Energy Savings 1 End Use | V1: Energy Savings 1 Value | W1: Energy Savings 1 Fuel Type | X1: Energy Savings 1 Units | Y1: Energy Savings 2 End Use | Z1: Energy Savings 2 Value | AA1: Energy Savings 2 Fuel Type | AB1: Energy Savings 2 Units | AC1: Energy Savings 3 End Use | AD1: Energy Savings 3 Value | AE1: Energy Savings 3 Fuel Type | AF1: Energy Savings 3 Units
A2: ='Code Output'!A702 -> 701 | B2: ='Code Output'!B702 -> refrigerator_electricity_efficient_residential_refrigerator_electricity_existing_residential | C2: ='Code Output'!C702 -> residential | D2: ='Code Output'!D702 -> LIRRET_ER | E2: ='Code Output'!E702 -> RET_ER | F2: ='Code Output'!F702 -> Methaners | G2: ='Code Output'!G702 -> ElecCo | H2: ='Code Output'!H702 -> refrigerator_electricity_existing_residential | ... AC2: ='Code Output'!AC702 -> 0
B5: RDR | C5: 0.03
B6: baseline cost | C6: 850 | F6: Instead
C7: . | G7: Year
G8: 1 | H8: =G8+1 -> 2 | I8: =H8+1 -> 3 | J8: =I8+1 -> 4 | K8: =J8+1 -> 5 | L8: =K8+1 -> 6 | M8: =L8+1 -> 7 | N8: =M8+1 -> 8 | O8: =N8+1 -> 9 | ... U8: =T8+1 -> 15
F9: Measure Installed Yr1 Life Span
F10: New Baseline Cost (Yr1 $) | K10: =$C$6/$L$2 -> 85 | L10: =$C$6/$L$2 -> 85 | M10: =$C$6/$L$2 -> 85 | N10: =$C$6/$L$2 -> 85 | O10: =$C$6/$L$2 -> 85 | P10: =$C$6/$L$2 -> 85 | Q10: =$C$6/$L$2 -> 85 | R10: =$C$6/$L$2 -> 85 | ... T10: =$C$6/$L$2 -> 85
F11: Proper capital recovery cost | K11: 99.65 | L11: 99.65 | M11: 99.65 | N11: 99.65 | O11: 99.65 | P11: 99.65 | Q11: 99.65 | R11: 99.65 | S11: 99.65 | T11: 99.65
F13: Deferred Replacement Credit | G13: =NPV($C$5,G10:P10) -> 460.46127
F14: capital recovery DRC | G14: =NPV($C$5,G11:P11) -> 539.82313
